<?xml version="1.0" ?>
<!-- =================================================================================== -->
<!-- |    This document was autogenerated by xacro from /home/hrithik/work/agv_ws/src/diff_drive_sim/urdf/diff_drive_robot.xacro | -->
<!-- |    EDITING THIS FILE BY HAND IS NOT RECOMMENDED                                 | -->
<!-- =================================================================================== -->
<robot name="diff_drive_robot">
  <!-- Robot Base -->
  <link name="base_link">
    <visual>
      <geometry>
        <box size="0.42 0.31 0.18"/>
      </geometry>
      <material name="Cyan">
        <color rgba="0 1.0 1.0 1.0"/>
      </material>
    </visual>
    <collision>
      <geometry>
        <box size="0.42 0.31 0.18"/>
      </geometry>
    </collision>
    <inertial>
      <origin rpy="1.5707963267948966 0 1.5707963267948966" xyz="0 0 0"/>
      <mass value="15"/>
      <inertia ixx="0.261" ixy="0.0" ixz="0.0" iyy="0.34062499999999996" iyz="0.0" izz="0.16062500000000002"/>
    </inertial>
  </link>
  <!-- Robot Footprint -->
  <link name="base_footprint">
    <inertial>
      <origin rpy="1.5707963267948966 0 1.5707963267948966" xyz="0 0 0"/>
      <mass value="0"/>
      <inertia ixx="0.0" ixy="0.0" ixz="0.0" iyy="0.0" iyz="0.0" izz="0.0"/>
    </inertial>
  </link>
  <joint name="base_joint" type="fixed">
    <parent link="base_link"/>
    <child link="base_footprint"/>
    <origin rpy="0 0 0" xyz="0.0 0.0 -0.15000000000000002"/>
  </joint>
  <link name="drivewhl_l_link">
    <visual>
      <origin rpy="1.5707963267948966 0 0" xyz="0 0 0"/>
      <geometry>
        <cylinder length="0.04" radius="0.1"/>
      </geometry>
      <material name="Gray">
        <color rgba="0.5 0.5 0.5 1.0"/>
      </material>
    </visual>
    <collision>
      <origin rpy="1.5707963267948966 0 0" xyz="0 0 0"/>
      <geometry>
        <cylinder length="0.04" radius="0.1"/>
      </geometry>
    </collision>
    <inertial>
      <origin rpy="1.5707963267948966 0 0" xyz="0 0 0"/>
      <mass value="0.5"/>
      <inertia ixx="0.0013166666666666667" ixy="0" ixz="0" iyy="0.0013166666666666667" iyz="0" izz="0.0025000000000000005"/>
    </inertial>
  </link>
  <joint name="drivewhl_l_joint" type="continuous">
    <parent link="base_link"/>
    <child link="drivewhl_l_link"/>
    <origin rpy="0 0 0" xyz="-0.12 0.18 -0.05"/>
    <axis xyz="0 1 0"/>
    <limit effort="5.0" velocity="10.0"/>
  </joint>
  <link name="drivewhl_r_link">
    <visual>
      <origin rpy="1.5707963267948966 0 0" xyz="0 0 0"/>
      <geometry>
        <cylinder length="0.04" radius="0.1"/>
      </geometry>
      <material name="Gray">
        <color rgba="0.5 0.5 0.5 1.0"/>
      </material>
    </visual>
    <collision>
      <origin rpy="1.5707963267948966 0 0" xyz="0 0 0"/>
      <geometry>
        <cylinder length="0.04" radius="0.1"/>
      </geometry>
    </collision>
    <inertial>
      <origin rpy="1.5707963267948966 0 0" xyz="0 0 0"/>
      <mass value="0.5"/>
      <inertia ixx="0.0013166666666666667" ixy="0" ixz="0" iyy="0.0013166666666666667" iyz="0" izz="0.0025000000000000005"/>
    </inertial>
  </link>
  <joint name="drivewhl_r_joint" type="continuous">
    <parent link="base_link"/>
    <child link="drivewhl_r_link"/>
    <origin rpy="0 0 0" xyz="-0.12 -0.18 -0.05"/>
    <axis xyz="0 1 0"/>
    <limit effort="5.0" velocity="10.0"/>
  </joint>
  <!-- Front Caster -->
  <link name="front_caster">
    <visual>
      <geometry>
        <sphere radius="0.060000000000000026"/>
      </geometry>
      <material name="Cyan">
        <color rgba="0 1.0 1.0 1.0"/>
      </material>
    </visual>
    <collision>
      <origin rpy="0 0 0" xyz="0 0 0"/>
      <geometry>
        <sphere radius="0.060000000000000026"/>
      </geometry>
    </collision>
    <inertial>
      <mass value="0.5"/>
      <inertia ixx="0.0007200000000000006" ixy="0.0" ixz="0.0" iyy="0.0007200000000000006" iyz="0.0" izz="0.0007200000000000006"/>
    </inertial>
  </link>
  <joint name="caster_joint" type="fixed">
    <parent link="base_link"/>
    <child link="front_caster"/>
    <origin rpy="0 0 0" xyz="0.14 0.0 -0.09"/>
  </joint>
  <!-- IMU Sensor -->
  <link name="imu_link">
    <visual>
      <geometry>
        <box size="0.1 0.1 0.1"/>
      </geometry>
    </visual>
    <collision>
      <geometry>
        <box size="0.1 0.1 0.1"/>
      </geometry>
    </collision>
    <inertial>
      <origin rpy="1.5707963267948966 0 1.5707963267948966" xyz="0 0 0"/>
      <mass value="0.1"/>
      <inertia ixx="0.0001666666666666667" ixy="0.0" ixz="0.0" iyy="0.0001666666666666667" iyz="0.0" izz="0.0001666666666666667"/>
    </inertial>
  </link>
  <joint name="imu_joint" type="fixed">
    <parent link="base_link"/>
    <child link="imu_link"/>
    <origin xyz="0 0 0.01"/>
  </joint>
  <gazebo reference="imu_link">
    <sensor name="imu_sensor" type="imu">
      <plugin filename="libgz_imu_system.so" name="imu_plugin">
        <ros>
          <namespace>/robot</namespace>
          <remapping>imu_data/data:=imu</remapping>
        </ros>
        <initial_orientation_as_reference>false</initial_orientation_as_reference>
      </plugin>
      <always_on>true</always_on>
      <update_rate>100</update_rate>
      <visualize>false</visualize>
      <imu>
        <angular_velocity>
          <x>
            <noise type="gaussian">
              <mean>0.0</mean>
              <stddev>2e-4</stddev>
            </noise>
          </x>
          <y>
            <noise type="gaussian">
              <mean>0.0</mean>
              <stddev>2e-4</stddev>
            </noise>
          </y>
          <z>
            <noise type="gaussian">
              <mean>0.0</mean>
              <stddev>2e-4</stddev>
            </noise>
          </z>
        </angular_velocity>
        <linear_acceleration>
          <x>
            <noise type="gaussian">
              <mean>0.0</mean>
              <stddev>1.7e-2</stddev>
            </noise>
          </x>
          <y>
            <noise type="gaussian">
              <mean>0.0</mean>
              <stddev>1.7e-2</stddev>
            </noise>
          </y>
          <z>
            <noise type="gaussian">
              <mean>0.0</mean>
              <stddev>1.7e-2</stddev>
            </noise>
          </z>
        </linear_acceleration>
      </imu>
    </sensor>
  </gazebo>
  <!-- Differential Drive Plugin for Gazebo Fortress -->
  <gazebo>
    <plugin filename="libgz_ros2_control-system.so" name="gz_ros2_control">
      <ros>
        <namespace>/robot</namespace>
      </ros>
      <parameters>/home/hrithik/work/agv_ws/install/diff_drive_sim/share/diff_drive_sim/config/gz_ros2_control.yaml</parameters>
    </plugin>
  </gazebo>
  <!-- Gazebo differential drive joint configuration -->
  <gazebo>
    <plugin filename="libgz_diff_drive.so" name="diff_drive">
      <left_joint>drivewhl_l_joint</left_joint>
      <right_joint>drivewhl_r_joint</right_joint>
      <wheel_separation>0.4</wheel_separation>
      <wheel_radius>0.1</wheel_radius>
      <odom_publish_frequency>50</odom_publish_frequency>
      <max_linear_velocity>1.0</max_linear_velocity>
      <max_angular_velocity>2.0</max_angular_velocity>
      <topic_cmd_vel>/cmd_vel</topic_cmd_vel>
      <topic_odom>/odom</topic_odom>
      <frame_id_odom>odom</frame_id_odom>
      <child_frame_id>base_link</child_frame_id>
    </plugin>
  </gazebo>
  <!-- Lidar Sensor -->
  <link name="lidar_link">
    <inertial>
      <origin rpy="0 0 0" xyz="0 0 0"/>
      <mass value="0.125"/>
      <inertia ixx="0.001" ixy="0" ixz="0" iyy="0.001" iyz="0" izz="0.001"/>
    </inertial>
    <collision>
      <origin rpy="0 0 0" xyz="0 0 0"/>
      <geometry>
        <cylinder length="0.055" radius="0.0508"/>
      </geometry>
    </collision>
    <visual>
      <origin rpy="0 0 0" xyz="0 0 0"/>
      <geometry>
        <cylinder length="0.055" radius="0.0508"/>
      </geometry>
    </visual>
  </link>
  <joint name="lidar_joint" type="fixed">
    <parent link="base_link"/>
    <child link="lidar_link"/>
    <origin rpy="0 0 0" xyz="0 0 0.12"/>
  </joint>
  <gazebo reference="lidar_link">
    <sensor name="lidar" type="ray">
      <always_on>true</always_on>
      <visualize>false</visualize>
      <update_rate>5</update_rate>
      <ray>
        <scan>
          <horizontal>
            <samples>360</samples>
            <resolution>1.000000</resolution>
            <min_angle>0.000000</min_angle>
            <max_angle>6.280000</max_angle>
          </horizontal>
        </scan>
        <range>
          <min>0.120000</min>
          <max>3.5</max>
          <resolution>0.015000</resolution>
        </range>
        <noise>
          <type>gaussian</type>
          <mean>0.0</mean>
          <stddev>0.01</stddev>
        </noise>
      </ray>
      <plugin filename="libgz_ray_sensor.so" name="scan">
        <ros>
          <namespace>/robot</namespace>
          <remapping>ray_scan/points:=scan</remapping>
        </ros>
        <output_type>sensor_msgs/LaserScan</output_type>
        <frame_name>lidar_link</frame_name>
      </plugin>
    </sensor>
  </gazebo>
</robot>
